Workbook

Sheet Спецификация
A1: № п/п | B1: Наименование и техническая характеристика | C1: Тип, марка, обозначение документа, опросного листа | D1: Код оборудования, изделия, материала | E1: Поставщик | F1: Ед. изм. | G1: Кол-во | H1: Цена, руб. с НДС | I1: Сумма, руб. с НДС | J1: Масса единицы, кг | K1: Примечание
A2: ЛОГИСТИКА — ПЕРЕВОЗКА ГРУЗОВ (наша, точка А → точка Б; из ВОРов)
A3: ВОР 20 | B3: Перевозка грузов I класса автомобилями-самосвалами грузоподъемностью до 30 т по дорогам с усовершенствованным (асфальтобетонным, цементобетонным, железобетонным, обработанным органическим вяжущим) дорожным покрытием на расстояние 140 км | E3: Нерудка | F3: 1т груза | G3: 269 | H3: 900 | I3: =H3*G3 -> 242100 | K3: ВОР 01-01-01, логистика; Источник: 03-01/07.21П-ООС.ТЧ. л 47 (Файл: 03-01_07.21П- ПЗУ.pdf, стр.: 178 179)
A4: ВОР 4 | B4: Перевозка грузов I класса автомобилями-самосвалами грузоподъемностью до 15 т по дорогам с усовершенствованным (асфальтобетонным, цементобетонным, железобетонным, обработанным органическим вяжущим) дорожным покрытием на расстояние 140 км | E4: Нерудка | F4: 1т груза | G4: 26796.8 | H4: 900 | I4: =H4*G4 -> 24117120 | K4: ВОР 01-01-01, логистика; Источник: 03-01/07.21П-ПОС.ТЧ. Приложение Д л. 179,187 (Файл: 03-01_07.21П-КР.pdf, стр.: 179)
A5: ВОР 3 | B5: Перевозка грузов I класса автомобилями-самосвалами грузоподъемностью до 15 т по дорогам с усовершенствованным (асфальтобетонным, цементобетонным, железобетонным, обработанным органическим вяжущим) дорожным покрытием на расстояние 140 км | E5: Нерудка | F5: 1т груза | G5: 112.704 | H5: 900 | I5: =H5*G5 -> 101433.6 | K5: ВОР 04-01-01, логистика; Источник: 03-01/07.21П-ИОС.1.5. л.10 (Файл: 03-01_07.21П- ИОС.1.5.pdf, стр.: 10)
A6: ВОР 4 | B6: Перевозка грузов I класса автомобилями-самосвалами грузоподъемностью до 15 т по дорогам с усовершенствованным (асфальтобетонным, цементобетонным, железобетонным, обработанным органическим вяжущим) дорожным покрытием на расстояние 140 км | E6: Нерудка | F6: 1т груза | G6: 169.6 | H6: 900 | I6: =H6*G6 -> 152640 | K6: ВОР 06-01-01, логистика; Источник: 03-01/07.21П-ПОС.ТЧ. Приложение Д. л. 179 (Файл: 03-01_07.21П-ПОС.pdf, стр.: 1)
A7: ВОР 16 | B7: Перевозка грузов I класса автомобилями-самосвалами грузоподъемностью до 15 т по дорогам с усовершенствованным (асфальтобетонным, цементобетонным, железобетонным, обработанным органическим вяжущим) дорожным покрытием на расстояние 140 км | E7: Нерудка | F7: 1т груза | G7: 851.2 | H7: 900 | I7: =H7*G7 -> 766080 | K7: ВОР 06-01-01, логистика; Источник: 03-01/07.21П-ПОС.ТЧ. Приложение Д. л. 179 (Файл: 03-01_07.21П-ПОС.pdf, стр.: 1)
A8: ВОР 29 | B8: Перевозка грузов I класса автомобилями-самосвалами грузоподъемностью до 15 т по дорогам с усовершенствованным (асфальтобетонным, цементобетонным, железобетонным, обработанным органическим вяжущим) дорожным покрытием на расстояние 140 км | E8: Нерудка | F8: 1т груза | G8: 76.8 | H8: 900 | I8: =H8*G8 -> 69120 | K8: ВОР 06-01-01, логистика; Источник: 03-01/07.21П-ПОС.ТЧ. Приложение Д. л. 180 (Файл: 03-01_07.21П-ПОС.pdf, стр.: 1)
A9: ВОР 4 | B9: Перевозка грузов I класса автомобилями-самосвалами грузоподъемностью до 15 т по дорогам с усовершенствованным (асфальтобетонным, цементобетонным, железобетонным, обработанным органическим вяжущим) дорожным покрытием на расстояние 140 км | E9: Нерудка | F9: 1т груза | G9: 228.8 | H9: 900 | I9: =H9*G9 -> 205920 | K9: ВОР 06-01-02, логистика; Источник: 03-01/07.21П-ПОС.ТЧ. Приложение Д. л. 186 (Файл: 03-01_07.21П-ПОС.pdf, стр.: 1)
A10: ВОР 15 | B10: Перевозка грузов I класса автомобилями-самосвалами грузоподъемностью до 15 т по дорогам с усовершенствованным (асфальтобетонным, цементобетонным, железобетонным, обработанным органическим вяжущим) дорожным покрытием на расстояние 140 км | E10: Нерудка | F10: 1т груза | G10: 30.4 | H10: 900 | I10: =H10*G10 -> 27360 | K10: ВОР 06-01-02, логистика; Источник: 03-01/07.21П-ПОС.ТЧ. Приложение Д. л. 181-182 (Файл: 03-01_07.21П-ПОС.pdf, стр.: 1)
A11: ВОР 25 | B11: Перевозка грузов I класса автомобилями-самосвалами грузоподъемностью до 15 т по дорогам с усовершенствованным (асфальтобетонным, цементобетонным, железобетонным, обработанным органическим вяжущим) дорожным покрытием на расстояние 140 км | E11: Нерудка | F11: 1т груза | G11: 625.6 | H11: 900 | I11: =H11*G11 -> 563040 | K11: ВОР 06-01-02, логистика; Источник: 03-01/07.21П-ПОС.ТЧ. Приложение Д. л. 186 (Файл: 03-01_07.21П-ПОС.pdf, стр.: 1)
A12: ВОР 37 | B12: Перевозка грузов I класса автомобилями-самосвалами грузоподъемностью до 15 т по дорогам с усовершенствованным (асфальтобетонным, цементобетонным, железобетонным, обработанным органическим вяжущим) дорожным покрытием на расстояние 140 км | E12: Нерудка | F12: 1т груза | G12: 104 | H12: 900 | I12: =H12*G12 -> 93600 | K12: ВОР 06-01-02, логистика; Источник: 03-01/07.21П-ПОС.ТЧ. Приложение Д. л. 181-182 (Файл: 03-01_07.21П-ПОС.pdf, стр.: 1)
A13: ВОР 52 | B13: Перевозка грузов I класса автомобилями-самосвалами грузоподъемностью до 15 т по дорогам с усовершенствованным (асфальтобетонным, цементобетонным, железобетонным, обработанным органическим вяжущим) дорожным покрытием на расстояние 140 км | E13: Нерудка | F13: 1т груза | G13: 1510.4 | H13: 900 | I13: =H13*G13 -> 1359360 | K13: ВОР 06-01-02, логистика; Источник: 03-01/07.21П-ПОС.ТЧ. Приложение Д. л. 186 (Файл: 03-01_07.21П-ПОС.pdf, стр.: 1)
A14: ВОР 65 | B14: Перевозка грузов I класса автомобилями-самосвалами грузоподъемностью до 15 т по дорогам с усовершенствованным (асфальтобетонным, цементобетонным, железобетонным, обработанным органическим вяжущим) дорожным покрытием на расстояние 140 км | E14: Нерудка | F14: 1т груза | G14: 329.6 | H14: 900 | I14: =H14*G14 -> 296640 | K14: ВОР 06-01-02, логистика; Источник: 03-01/07.21П-ПОС.ТЧ. Приложение Д. л. 184 (Файл: 03-01_07.21П-ПОС.pdf, стр.: 1)
... A17: ВОР 26 | B17: Перевозка грузов I класса автомобилями-самосвалами грузоподъемностью до 15 т по дорогам с усовершенствованным (асфальтобетонным, цементобетонным, железобетонным, обработанным органическим вяжущим) дорожным покрытием на расстояние 140 км | E17: Нерудка | F17: 1т груза | G17: 124.03 | H17: 900 | I17: =H17*G17 -> 111627 | K17: ВОР 07-01-04, логистика; Источник: 03-01/07.21П-ИОС.1.4.ГЧ л.2 (Файл: 03-01_07.21П- ИОС.1.4.pdf, стр.: 18 19 20 21)
A18: 5.1. | B18: СИСТЕМА ЭЛЕКТРОСНАБЖЕНИЯ
B19: Электрооборудование 03-01/07.21П-ИОС-1.1.СО
A20: 1 | B20: ЩИТОВОЕ ОБОРУДОВАНИЕ
B21: Главный распределительный щит, ГРЩ-1 | C21: Согласно схеме см. ГЧ | E21: Россия | F21: компл. | G21: 1 | H21: 959419.25 | I21: =H21*G21 -> 959419.25
B22: Главный распределительный щит, ГРЩ-2 | C22: Согласно схеме см. ГЧ | E22: Россия | F22: компл. | G22: 1 | H22: 2812830 | I22: =H22*G22 -> 2812830
B23: Щит силовой навесного исполнения, ЩС1 | C23: Согласно схеме см. ГЧ | E23: Россия | F23: компл. | G23: 1 | H23: 66620.7 | I23: =H23*G23 -> 66620.7
B24: Щит силовой навесного исполнения, ЩС2 | C24: Согласно схеме см. ГЧ | E24: Россия | F24: компл. | G24: 1 | H24: 94135.83 | I24: =H24*G24 -> 94135.83
B25: Щит силовой навесного исполнения, ЩС3 | C25: Согласно схеме см. ГЧ | E25: Россия | F25: компл. | G25: 1 | H25: 40035.53 | I25: =H25*G25 -> 40035.53
B26: Щит силовой навесного исполнения, ЩС4 | C26: Согласно схеме см. ГЧ | E26: Россия | F26: компл. | G26: 1 | H26: 46940.94 | I26: =H26*G26 -> 46940.94
B27: Щит силовой навесного исполнения, ЩС5 | C27: Согласно схеме см. ГЧ | E27: Россия | F27: компл. | G27: 1 | H27: 53529.39 | I27: =H27*G27 -> 53529.39
B28: Щит силовой навесного исполнения, ЩС6 | C28: Согласно схеме см. ГЧ | E28: Россия | F28: компл. | G28: 1 | H28: 56081.52 | I28: =H28*G28 -> 56081.52
B29: Щит силовой навесного исполнения, ЩС7 | C29: Согласно схеме см. ГЧ | E29: Россия | F29: компл. | G29: 1 | H29: 47192.31 | I29: =H29*G29 -> 47192.31
B30: Щит силовой навесного исполнения, ЩС8 | C30: Согласно схеме см. ГЧ | E30: Россия | F30: компл. | G30: 1 | H30: 53529.39 | I30: =H30*G30 -> 53529.39
B31: Щит силовой навесного исполнения, ЩС9 | C31: Согласно схеме см. ГЧ | E31: Россия | F31: компл. | G31: 1 | H31: 40451.43 | I31: =H31*G31 -> 40451.43
B32: Щит силовой навесного исполнения, ЩС10 | C32: Согласно схеме см. ГЧ | E32: Россия | F32: компл. | G32: 1 | H32: 28839.95 | I32: =H32*G32 -> 28839.95
... B48: Конденсаторная установка | C48: КРМ-0,4-25-5 У3 | E48: Россия | F48: компл. | G48: 1 | H48: 73170.72 | I48: =H48*G48 -> 73170.72
A49: 2 | B49: ЭЛЕКТРОУСТАНОВОЧНЫЕ ИЗДЕЛИЯ
B50: Розетка комп. одинарная двухполюсная с защитным контактом, IP20 | E50: Россия | F50: шт. | G50: 107 | H50: 639.2556 | I50: =H50*G50 -> 68400.349 | K50: отличительной расцветки
B51: Розетка одинарная двухполюсная с защитным контактом, IP20 | E51: Россия | F51: шт. | G51: 152 | H51: 165.066 | I51: =H51*G51 -> 25090.032
B52: Розетка одинарная двухполюсная с защитным контактом, IP44 | E52: Россия | F52: шт. | G52: 150 | H52: 286.6146 | I52: =H52*G52 -> 42992.19
B53: Коробка для э/у изделий 1-постовая | E53: Россия | F53: шт. | G53: 409 | H53: 11.0532 | I53: =H53*G53 -> 4520.7588
B54: Розетка наружной установки 380В | E54: Россия | F54: шт. | G54: 4 | H54: 1680 | I54: =H54*G54 -> 6720
B55: Коробка ответвительная скрытой установки | E55: Россия | F55: шт. | G55: 740 | H55: 79.4342 | I55: =H55*G55 -> 58781.308
A56: 3 | B56: КАБЕЛЬНАЯ ПРОДУКЦИЯ | K56: в СО этот раздел № 4 (в оригинале номер 3 пропущен)
B57: Кабель с медными жилами, с ПВХ изоляцией | C57: ВВГнг(А)-HF 3х2,5 | E57: Россия | F57: м | G57: 11406 | H57: 130 | I57: =H57*G57 -> 1482780
...

Sheet НЕТ В СО (из ВОРов)
A1: ЧТО ЕСТЬ В ВОРах, НО ОТСУТСТВУЕТ В СПЕЦИФИКАЦИЯХ (СО)
A2: Правило: позиция есть и в СО, и в ВОРе — берём как в СО. В СО нет, а в ВОРе есть — берём по ВОРу. Складывать СО и ВОР нельзя.
A3: Здесь только второе — то, чего в СО нет вообще. Это то, что придётся закупать и расценивать сверх спецификаций.
A4: Кол-во, цена и сумма подтянуты формулами с листа «Спецификация» — править их надо там, здесь пересчитается само. Колонка J — номер строки-источника.
A5: Блок ВОР 02-01-11 (ТХ.2) на листе «Спецификация» сокращён с 369 строк до 3: остальные 366 были дублями ТХ.2.СО. Их цены (257 100 ₽) перенесены на строки ТХ.2.СО, ИТОГО книги не изменилось.
A7: № | B7: Раздел / дисциплина ВОР | C7: № по ВОР | D7: Наименование | E7: Тип, марка | F7: Ед. изм. | G7: Кол-во | H7: Цена, руб. с НДС | I7: Сумма, руб. с НДС | J7: Строка в «Спецификации» | K7: Статус цены | L7: Примечание в книге
A8: Логистика — перевозка грузов (из ВОРов) (15 поз.)
A9: 1 | B9: Логистика — перевозка грузов (из ВОРов) | C9: ВОР 20 | D9: Перевозка грузов I класса автомобилями-самосвалами грузоподъемностью до 30 т по дорогам с усовершенствованным (асфальтобетонным, цементобетонным, железобетонным, обработанным органическим вяжущим) дорожным покрытием на расстояние 140 км | E9: 03-01/07.21П-ООС.ТЧ. л 47 (Файл: 03-01_07.21П- ПЗУ.pdf, стр.: 178 179) | F9: 1т груза | G9: =Спецификация!G3 -> 269 | H9: =Спецификация!H3 -> 900 | I9: =Спецификация!I3 -> 242100 | J9: 3 | K9: =IF(H9=0,"НЕТ ЦЕНЫ","проценено") -> проценено | L9: ВОР 01-01-01, логистика
A10: 2 | B10: Логистика — перевозка грузов (из ВОРов) | C10: ВОР 4 | D10: Перевозка грузов I класса автомобилями-самосвалами грузоподъемностью до 15 т по дорогам с усовершенствованным (асфальтобетонным, цементобетонным, железобетонным, обработанным органическим вяжущим) дорожным покрытием на расстояние 140 км | E10: 03-01/07.21П-ПОС.ТЧ. Приложение Д л. 179,187 (Файл: 03-01_07.21П-КР.pdf, стр.: 179) | F10: 1т груза | G10: =Спецификация!G4 -> 26796.8 | H10: =Спецификация!H4 -> 900 | I10: =Спецификация!I4 -> 24117120 | J10: 4 | K10: =IF(H10=0,"НЕТ ЦЕНЫ","проценено") -> проценено | L10: ВОР 01-01-01, логистика
A11: 3 | B11: Логистика — перевозка грузов (из ВОРов) | C11: ВОР 3 | D11: Перевозка грузов I класса автомобилями-самосвалами грузоподъемностью до 15 т по дорогам с усовершенствованным (асфальтобетонным, цементобетонным, железобетонным, обработанным органическим вяжущим) дорожным покрытием на расстояние 140 км | E11: 03-01/07.21П-ИОС.1.5. л.10 (Файл: 03-01_07.21П- ИОС.1.5.pdf, стр.: 10) | F11: т груз а | G11: =Спецификация!G5 -> 112.704 | H11: =Спецификация!H5 -> 900 | I11: =Спецификация!I5 -> 101433.6 | J11: 5 | K11: =IF(H11=0,"НЕТ ЦЕНЫ","проценено") -> проценено | L11: ВОР 04-01-01, логистика
A12: 4 | B12: Логистика — перевозка грузов (из ВОРов) | C12: ВОР 4 | D12: Перевозка грузов I класса автомобилями-самосвалами грузоподъемностью до 15 т по дорогам с усовершенствованным (асфальтобетонным, цементобетонным, железобетонным, обработанным органическим вяжущим) дорожным покрытием на расстояние 140 км | E12: 03-01/07.21П-ПОС.ТЧ. Приложение Д. л. 179 (Файл: 03-01_07.21П-ПОС.pdf, стр.: 1) | F12: 1т груза | G12: =Спецификация!G6 -> 169.6 | H12: =Спецификация!H6 -> 900 | I12: =Спецификация!I6 -> 152640 | J12: 6 | K12: =IF(H12=0,"НЕТ ЦЕНЫ","проценено") -> проценено | L12: ВОР 06-01-01, логистика
A13: 5 | B13: Логистика — перевозка грузов (из ВОРов) | C13: ВОР 16 | D13: Перевозка грузов I класса автомобилями-самосвалами грузоподъемностью до 15 т по дорогам с усовершенствованным (асфальтобетонным, цементобетонным, железобетонным, обработанным органическим вяжущим) дорожным покрытием на расстояние 140 км | E13: 03-01/07.21П-ПОС.ТЧ. Приложение Д. л. 179 (Файл: 03-01_07.21П-ПОС.pdf, стр.: 1) | F13: 1т груза | G13: =Спецификация!G7 -> 851.2 | H13: =Спецификация!H7 -> 900 | I13: =Спецификация!I7 -> 766080 | J13: 7 | K13: =IF(H13=0,"НЕТ ЦЕНЫ","проценено") -> проценено | L13: ВОР 06-01-01, логистика
A14: 6 | B14: Логистика — перевозка грузов (из ВОРов) | C14: ВОР 29 | D14: Перевозка грузов I класса автомобилями-самосвалами грузоподъемностью до 15 т по дорогам с усовершенствованным (асфальтобетонным, цементобетонным, железобетонным, обработанным органическим вяжущим) дорожным покрытием на расстояние 140 км | E14: 03-01/07.21П-ПОС.ТЧ. Приложение Д. л. 180 (Файл: 03-01_07.21П-ПОС.pdf, стр.: 1) | F14: 1т груза | G14: =Спецификация!G8 -> 76.8 | H14: =Спецификация!H8 -> 900 | I14: =Спецификация!I8 -> 69120 | J14: 8 | K14: =IF(H14=0,"НЕТ ЦЕНЫ","проценено") -> проценено | L14: ВОР 06-01-01, логистика
A15: 7 | B15: Логистика — перевозка грузов (из ВОРов) | C15: ВОР 4 | D15: Перевозка грузов I класса автомобилями-самосвалами грузоподъемностью до 15 т по дорогам с усовершенствованным (асфальтобетонным, цементобетонным, железобетонным, обработанным органическим вяжущим) дорожным покрытием на расстояние 140 км | E15: 03-01/07.21П-ПОС.ТЧ. Приложение Д. л. 186 (Файл: 03-01_07.21П-ПОС.pdf, стр.: 1) | F15: 1т | G15: =Спецификация!G9 -> 228.8 | H15: =Спецификация!H9 -> 900 | I15: =Спецификация!I9 -> 205920 | J15: 9 | K15: =IF(H15=0,"НЕТ ЦЕНЫ","проценено") -> проценено | L15: ВОР 06-01-02, логистика
A16: 8 | B16: Логистика — перевозка грузов (из ВОРов) | C16: ВОР 15 | D16: Перевозка грузов I класса автомобилями-самосвалами грузоподъемностью до 15 т по дорогам с усовершенствованным (асфальтобетонным, цементобетонным, железобетонным, обработанным органическим вяжущим) дорожным покрытием на расстояние 140 км | E16: 03-01/07.21П-ПОС.ТЧ. Приложение Д. л. 181-182 (Файл: 03-01_07.21П-ПОС.pdf, стр.: 1) | F16: 1т груза | G16: =Спецификация!G10 -> 30.4 | H16: =Спецификация!H10 -> 900 | I16: =Спецификация!I10 -> 27360 | J16: 10 | K16: =IF(H16=0,"НЕТ ЦЕНЫ","проценено") -> проценено | L16: ВОР 06-01-02, логистика
A17: 9 | B17: Логистика — перевозка грузов (из ВОРов) | C17: ВОР 25 | D17: Перевозка грузов I класса автомобилями-самосвалами грузоподъемностью до 15 т по дорогам с усовершенствованным (асфальтобетонным, цементобетонным, железобетонным, обработанным органическим вяжущим) дорожным покрытием на расстояние 140 км | E17: 03-01/07.21П-ПОС.ТЧ. Приложение Д. л. 186 (Файл: 03-01_07.21П-ПОС.pdf, стр.: 1) | F17: 1т | G17: =Спецификация!G11 -> 625.6 | H17: =Спецификация!H11 -> 900 | I17: =Спецификация!I11 -> 563040 | J17: 11 | K17: =IF(H17=0,"НЕТ ЦЕНЫ","проценено") -> проценено | L17: ВОР 06-01-02, логистика
A18: 10 | B18: Логистика — перевозка грузов (из ВОРов) | C18: ВОР 37 | D18: Перевозка грузов I класса автомобилями-самосвалами грузоподъемностью до 15 т по дорогам с усовершенствованным (асфальтобетонным, цементобетонным, железобетонным, обработанным органическим вяжущим) дорожным покрытием на расстояние 140 км | E18: 03-01/07.21П-ПОС.ТЧ. Приложение Д. л. 181-182 (Файл: 03-01_07.21П-ПОС.pdf, стр.: 1) | F18: 1т груза | G18: =Спецификация!G12 -> 104 | H18: =Спецификация!H12 -> 900 | I18: =Спецификация!I12 -> 93600 | J18: 12 | K18: =IF(H18=0,"НЕТ ЦЕНЫ","проценено") -> проценено | L18: ВОР 06-01-02, логистика
A19: 11 | B19: Логистика — перевозка грузов (из ВОРов) | C19: ВОР 52 | D19: Перевозка грузов I класса автомобилями-самосвалами грузоподъемностью до 15 т по дорогам с усовершенствованным (асфальтобетонным, цементобетонным, железобетонным, обработанным органическим вяжущим) дорожным покрытием на расстояние 140 км | E19: 03-01/07.21П-ПОС.ТЧ. Приложение Д. л. 186 (Файл: 03-01_07.21П-ПОС.pdf, стр.: 1) | F19: 1т груза | G19: =Спецификация!G13 -> 1510.4 | H19: =Спецификация!H13 -> 900 | I19: =Спецификация!I13 -> 1359360 | J19: 13 | K19: =IF(H19=0,"НЕТ ЦЕНЫ","проценено") -> проценено | L19: ВОР 06-01-02, логистика
A20: 12 | B20: Логистика — перевозка грузов (из ВОРов) | C20: ВОР 65 | D20: Перевозка грузов I класса автомобилями-самосвалами грузоподъемностью до 15 т по дорогам с усовершенствованным (асфальтобетонным, цементобетонным, железобетонным, обработанным органическим вяжущим) дорожным покрытием на расстояние 140 км | E20: 03-01/07.21П-ПОС.ТЧ. Приложение Д. л. 184 (Файл: 03-01_07.21П-ПОС.pdf, стр.: 1) | F20: 1т груза | G20: =Спецификация!G14 -> 329.6 | H20: =Спецификация!H14 -> 900 | I20: =Спецификация!I14 -> 296640 | J20: 14 | K20: =IF(H20=0,"НЕТ ЦЕНЫ","проценено") -> проценено | L20: ВОР 06-01-02, логистика
... A23: 15 | B23: Логистика — перевозка грузов (из ВОРов) | C23: ВОР 26 | D23: Перевозка грузов I класса автомобилями-самосвалами грузоподъемностью до 15 т по дорогам с усовершенствованным (асфальтобетонным, цементобетонным, железобетонным, обработанным органическим вяжущим) дорожным покрытием на расстояние 140 км | E23: 03-01/07.21П-ИОС.1.4.ГЧ л.2 (Файл: 03-01_07.21П- ИОС.1.4.pdf, стр.: 18 19 20 21) | F23: 1т груза | G23: =Спецификация!G17 -> 124.03 | H23: =Спецификация!H17 -> 900 | I23: =Спецификация!I17 -> 111627 | J23: 17 | K23: =IF(H23=0,"НЕТ ЦЕНЫ","проценено") -> проценено | L23: ВОР 07-01-04, логистика
D24: Итого по разделу | I24: =SUM(I9:I23) -> 35451481
A26: Позиции из ВОРов, вставленные в разделы СО (ИОС) (46 поз.)
A27: 16 | B27: Позиции из ВОРов, вставленные в разделы СО (ИОС) | C27: ВОР 154 | D27: Умывальник полуфарфоровый и фарфоровый прямоугольный с кронштейнами, сифоном бутылочным из латуни, выпуском, одно отверстие под смеситель, смеситель с центральным подводом, набортный с двумя рукоятями, излив с развальцованным носиком, вынос излива 280 мм, размеры 450x330x150 мм | E27: 03-01/07.21П-ИОС 2.1.ГЧ Спецификация (Файл: 03- 01_07.21П-ИОС.2.pdf стр.: 1 2 3 4 5 6) | F27: к-т | G27: =Спецификация!G384 -> 68 | H27: =Спецификация!H384 -> 0 | I27: =Спецификация!I384 -> 0 | J27: 384 | K27: =IF(H27=0,"НЕТ ЦЕНЫ","проценено") -> НЕТ ЦЕНЫ | L27: ВОР, нет в СО
A28: 17 | B28: Позиции из ВОРов, вставленные в разделы СО (ИОС) | C28: ВОР 156 | D28: Унитаз керамический напольный в комплекте с бачком, с косым выпуском, размеры 360x620x765 мм | E28: 03-01/07.21П-ИОС 2.1.ГЧ Спецификация (Файл: 03- 01_07.21П-ИОС.2.pdf стр.: 1 2 3 4 5 6) | F28: к-т | G28: =Спецификация!G385 -> 51 | H28: =Спецификация!H385 -> 0 | I28: =Спецификация!I385 -> 0 | J28: 385 | K28: =IF(H28=0,"НЕТ ЦЕНЫ","проценено") -> НЕТ ЦЕНЫ | L28: ВОР, нет в СО
A29: 18 | B29: Позиции из ВОРов, вставленные в разделы СО (ИОС) | C29: ВОР 158 | D29: Писсуар настенный керамический, подвод воды скрытый, вход слива скрытый, размеры 275x310x540 мм, с краном нажимным, центральным подводом, набортный, размеры 215x104x50 мм | E29: 03-01/07.21П-ИОС 2.1.ГЧ Спецификация (Файл: 03- 01_07.21П-ИОС.2.pdf стр.: 1 2 3 4 5 6) | F29: шт. | G29: =Спецификация!G386 -> 10 | H29: =Спецификация!H386 -> 0 | I29: =Спецификация!I386 -> 0 | J29: 386 | K29: =IF(H29=0,"НЕТ ЦЕНЫ","проценено") -> НЕТ ЦЕНЫ | L29: ВОР, нет в СО
A30: 19 | B30: Позиции из ВОРов, вставленные в разделы СО (ИОС) | C30: ВОР 160 | D30: Поддон душевой стальной эмалированный мелкий, тип ПДСм-800 высотой 150 мм, пластмассовый унифицированный сифон, пластмассовый выпуск с диаметром выпускной решетки 70 мм, диаметр сливного отверстия 50 мм, диаметр сливной гофры 40/50 мм | E30: 03-01/07.21П-ИОС 2.1.ГЧ Спецификация (Файл: 03- 01_07.21П-ИОС.2.pdf стр.: 1 2 3 4 5 6) | F30: к-т | G30: =Спецификация!G387 -> 32 | H30: =Спецификация!H387 -> 0 | I30: =Спецификация!I387 -> 0 | J30: 387 | K30: =IF(H30=0,"НЕТ ЦЕНЫ","проценено") -> НЕТ ЦЕНЫ | L30: ВОР, нет в СО
A31: 20 | B31: Позиции из ВОРов, вставленные в разделы СО (ИОС) | C31: ВОР 162 | D31: Мойка стальная эмалированная, одна чаша, с креплениями, с пластмассовым бутылочным сифоном и выпуском, размеры 500x500x160 мм | E31: 03-01/07.21П-ИОС 2.1.ГЧ Спецификация (Файл: 03- 01_07.21П-ИОС.2.pdf стр.: 1 2 3 4 5 6) | F31: к-т | G31: =Спецификация!G388 -> 8 | H31: =Спецификация!H388 -> 0 | I31: =Спецификация!I388 -> 0 | J31: 388 | K31: =IF(H31=0,"НЕТ ЦЕНЫ","проценено") -> НЕТ ЦЕНЫ | L31: ВОР, нет в СО
A32: 21 | B32: Позиции из ВОРов, вставленные в разделы СО (ИОС) | C32: ВОР 164 | D32: Трубы полипропиленовые для систем водоотведения, диаметр 50 мм | E32: 03-01/07.21П-ИОС 2.1.ГЧ Спецификация (Файл: 03- 01 07.21П-ИОС.2.pdf стр.: 1 2 3 4 5 6) | F32: м | G32: =Спецификация!G389 -> 269.46 | H32: =Спецификация!H389 -> 0 | I32: =Спецификация!I389 -> 0 | J32: 389 | K32: =IF(H32=0,"НЕТ ЦЕНЫ","проценено") -> НЕТ ЦЕНЫ | L32: ВОР, нет в СО
A33: 22 | B33: Позиции из ВОРов, вставленные в разделы СО (ИОС) | C33: ВОР 166 | D33: Трубы полипропиленовые для систем водоотведения, диаметр 110 мм | E33: 03-01/07.21П-ИОС 2.1.ГЧ Спецификация (Файл: 03- 01 07.21П-ИОС.2.pdf стр.: 1 2 3 4 5 6) | F33: м | G33: =Спецификация!G390 -> 449.1 | H33: =Спецификация!H390 -> 0 | I33: =Спецификация!I390 -> 0 | J33: 390 | K33: =IF(H33=0,"НЕТ ЦЕНЫ","проценено") -> НЕТ ЦЕНЫ | L33: ВОР, нет в СО
A34: 23 | B34: Позиции из ВОРов, вставленные в разделы СО (ИОС) | C34: ВОР 168 | D34: Трубы ХПВХ, номинальное давление 1,0 МПа, диаметр 110 мм, толщина стенки 5,3 мм, 1000 мм | E34: 03-01/07.21П-ИОС 2.1.ГЧ Спецификация (Файл: 03- 01_07.21П-ИОС.2.pdf стр.: 1 2 3 4 5 6) | F34: шт. | G34: =Спецификация!G391 -> 98.14 | H34: =Спецификация!H391 -> 0 | I34: =Спецификация!I391 -> 0 | J34: 391 | K34: =IF(H34=0,"НЕТ ЦЕНЫ","проценено") -> НЕТ ЦЕНЫ | L34: ВОР, нет в СО
A35: 24 | B35: Позиции из ВОРов, вставленные в разделы СО (ИОС) | C35: ВОР 170 | D35: Муфты противопожарные для пластиковых труб: РТМК-110 | E35: 03-01/07.21П-ИОС 2.1.ГЧ Спецификация (Файл: 03- 01 07.21П-ИОС.2.pdf стр.: 1 2 3 4 5 6) | F35: шт. | G35: =Спецификация!G392 -> 20 | H35: =Спецификация!H392 -> 0 | I35: =Спецификация!I392 -> 0 | J35: 392 | K35: =IF(H35=0,"НЕТ ЦЕНЫ","проценено") -> НЕТ ЦЕНЫ | L35: ВОР, нет в СО
A36: 25 | B36: Позиции из ВОРов, вставленные в разделы СО (ИОС) | C36: ВОР 173 | D36: Отвод 87,5° полипропиленовый для систем водоотведения, диаметр 50 мм | E36: 03-01/07.21П-ИОС 2.1.ГЧ Спецификация (Файл: 03- 01 07.21П-ИОС.2.pdf стр.: 1 2 3 4 5 6) | F36: шт. | G36: =Спецификация!G393 -> 76 | H36: =Спецификация!H393 -> 0 | I36: =Спецификация!I393 -> 0 | J36: 393 | K36: =IF(H36=0,"НЕТ ЦЕНЫ","проценено") -> НЕТ ЦЕНЫ | L36: ВОР, нет в СО
A37: 26 | B37: Позиции из ВОРов, вставленные в разделы СО (ИОС) | C37: ВОР 174 | D37: Отвод 87,5° полипропиленовый для систем водоотведения, диаметр 110 мм | E37: 03-01/07.21П-ИОС 2.1.ГЧ Спецификация (Файл: 03- 01 07.21П-ИОС.2.pdf стр.: 1 2 3 4 5 6) | F37: шт. | G37: =Спецификация!G394 -> 117 | H37: =Спецификация!H394 -> 0 | I37: =Спецификация!I394 -> 0 | J37: 394 | K37: =IF(H37=0,"НЕТ ЦЕНЫ","проценено") -> НЕТ ЦЕНЫ | L37: ВОР, нет в СО
A38: 27 | B38: Позиции из ВОРов, вставленные в разделы СО (ИОС) | C38: ВОР 175 | D38: Тройник полипропиленовый для систем водоотведения, диаметр 50 мм | E38: 03-01/07.21П-ИОС 2.1.ГЧ Спецификация (Файл: 03- 01 07.21П-ИОС.2.pdf стр.: 1 2 3 4 5 6) | F38: шт. | G38: =Спецификация!G395 -> 49 | H38: =Спецификация!H395 -> 0 | I38: =Спецификация!I395 -> 0 | J38: 395 | K38: =IF(H38=0,"НЕТ ЦЕНЫ","проценено") -> НЕТ ЦЕНЫ | L38: ВОР, нет в СО
... A51: 40 | B51: Позиции из ВОРов, вставленные в разделы СО (ИОС) | C51: ВОР 202 | D51: Тройник полипропиленовый для систем водоотведения, диаметр 110 мм | E51: 03-01/07.21П-ИОС 2.1.ГЧ Спецификация (Файл: 03- 01_07.21П-ИОС.2.pdf стр.: 1 2 3 4 5 6) | F51: шт. | G51: =Спецификация!G408 -> 21 | H51: =Спецификация!H408 -> 0 | I51: =Спецификация!I408 -> 0 | J51: 408 | K51: =IF(H51=0,"НЕТ ЦЕНЫ","проценено") -> НЕТ ЦЕНЫ | L51: ВОР, нет в СО
A52: 41 | B52: Позиции из ВОРов, вставленные в разделы СО (ИОС) | C52: ВОР 74 | D52: Муфта полиэтиленовая соединительная для дренажных труб, диаметр 160 мм | E52: 03-01/07.21П-ИОС 3.1 ГЧ. Спецификация л. 1 (Файл: 03-01_07.21П-ИОС3.1.pdf, стр.: 1) | F52: шт. | G52: =Спецификация!G423 -> 35 | H52: =Спецификация!H423 -> 0 | I52: =Спецификация!I423 -> 0 | J52: 423 | K52: =IF(H52=0,"НЕТ ЦЕНЫ","проценено") -> НЕТ ЦЕНЫ | L52: ВОР, нет в СО
A53: 42 | B53: Позиции из ВОРов, вставленные в разделы СО (ИОС) | C53: ВОР 85 | D53: Люк чугунный с решеткой для дождеприемного колодца, номинальная нагрузка 15 кН, диаметр лаза 600 мм | E53: 03-01/07.21П-ИОС 3.1 ГЧ. Спецификация л. 1 (Файл: 03-01_07.21П-ИОС3.1.pdf, стр.: 1) | F53: шт. | G53: =Спецификация!G424 -> 22 | H53: =Спецификация!H424 -> 0 | I53: =Спецификация!I424 -> 0 | J53: 424 | K53: =IF(H53=0,"НЕТ ЦЕНЫ","проценено") -> НЕТ ЦЕНЫ | L53: ВОР, нет в СО
A54: 43 | B54: Позиции из ВОРов, вставленные в разделы СО (ИОС) | C54: ВОР 87 | D54: Трубы дренажные гофрированные двухслойные полипропиленовые, SN16, диаметр 200 мм | E54: 03-01/07.21П-ИОС 3.1 ГЧ. Спецификация л. 2 (Файл: 03-01_07.21П-ИОС3.1.pdf, стр.: 1) | F54: м | G54: =Спецификация!G425 -> 25.25 | H54: =Спецификация!H425 -> 0 | I54: =Спецификация!I425 -> 0 | J54: 425 | K54: =IF(H54=0,"НЕТ ЦЕНЫ","проценено") -> НЕТ ЦЕНЫ | L54: ВОР, нет в СО
A55: 44 | B55: Позиции из ВОРов, вставленные в разделы СО (ИОС) | C55: ВОР 89 | D55: Трубы дренажные гофрированные двухслойные полипропиленовые, SN16, диаметр 250 мм | E55: 03-01/07.21П-ИОС 3.1 ГЧ. Спецификация л. 2 (Файл: 03-01_07.21П-ИОС3.1.pdf, стр.: 1) | F55: м | G55: =Спецификация!G426 -> 363.6 | H55: =Спецификация!H426 -> 0 | I55: =Спецификация!I426 -> 0 | J55: 426 | K55: =IF(H55=0,"НЕТ ЦЕНЫ","проценено") -> НЕТ ЦЕНЫ | L55: ВОР, нет в СО
A56: 45 | B56: Позиции из ВОРов, вставленные в разделы СО (ИОС) | C56: ВОР 91 | D56: Трубы дренажные гофрированные двухслойные полипропиленовые, SN16, диаметр 315 мм | E56: 03-01/07.21П-ИОС 3.1 ГЧ. Спецификация л. 2 (Файл: 03-01_07.21П-ИОС3.1.pdf, стр.: 1) | F56: м | G56: =Спецификация!G427 -> 303 | H56: =Спецификация!H427 -> 0 | I56: =Спецификация!I427 -> 0 | J56: 427 | K56: =IF(H56=0,"НЕТ ЦЕНЫ","проценено") -> НЕТ ЦЕНЫ | L56: ВОР, нет в СО
...

Sheet Сверка ТХ.2
A1: Сверка ВОР 02-01-11 (технологические решения) с оригиналом спецификации 03-01/07.21П-ТХ.2.СО
A2: Слева — позиции по СО (свод по всем 268 помещениям), справа — сумма количеств по строкам ВОРа, сопоставленным с этой позицией. Сопоставление по наименованию, поэтому у близких по названию позиций объём может быть отнесён к соседней строке — расхождения смотреть вместе с соседними строками.
A4: Наименование по ТХ.2.СО | B4: Ед. изм. | C4: Кол-во по СО | D4: Кол-во по ВОР | E4: Разница (ВОР − СО) | F4: Строк в ВОРе | G4: Статус
A5: Комплект принадлежностей для душевой: коврик нескользящий, полка для туалетных принадлежностей, вешалка настенная | B5: компл | C5: 1 | D5: 68 | E5: 67 | F5: 1 | G5: ВОР больше СО на 67
A6: Комплект принадлежностей для душевой: коврик нескользящий, занавеска, полка для туалетных принадлежностей, вешалка настенная | B6: шт | C6: 5 | D6: 68 | E6: 63 | F6: 1 | G6: ВОР больше СО на 63
A7: Диспенсер для бумажных полотенец. Сушилка для рук, настенная; Э: 1ф, 220В, 1.2кВт | B7: шт | C7: 25 | D7: 49 | E7: 24 | F7: 2 | G7: ВОР больше СО на 24
A8: Диспенсер для бумажных полотенец | B8: шт | C8: 17 | D8: 38 | E8: 21 | F8: 4 | G8: ВОР больше СО на 21
A9: Скамья гардеробная 854х390х475(h) мм | B9: шт | C9: 52 | D9: 68 | E9: 16 | F9: 5 | G9: ВОР больше СО на 16
A10: Стул для посетителей (материал обивки – к/з); 540х440х820(h) мм | B10: шт | C10: 75 | D10: 88 | E10: 13 | F10: 2 | G10: ВОР больше СО на 13
A11: Лампа настольная, 0,1 кВт, 220 В | B11: шт | C11: 11 | D11: 21 | E11: 10 | F11: 1 | G11: ВОР больше СО на 10
A12: Шкаф для раздевалок HPL пластик ТС 2-1 (2 секции) (64,5, В комплекте — верхняя полка, нижняя полка, штанга и крючок) (ДхВхШ) 624х1950х500 | B12: шт | C12: 20 | D12: 29 | E12: 9 | F12: 2 | G12: ВОР больше СО на 9
A13: Шкаф для раздевалок HPL ТС 1-10 300х500х1850 мм (запираемая распашная дверь, полка для головных уборов, перекладина для вешалки с крючками) | B13: шт | C13: 10 | D13: 18 | E13: 8 | F13: 1 | G13: ВОР больше СО на 8
A14: Многофункциональное устройство (копир/сканер/принтер), форматы А4 и А3; Э: 1 ф., 220 В, 0,6 кВт с возможностью печати фотографий | B14: шт | C14: 3 | D14: 11 | E14: 8 | F14: 1 | G14: ВОР больше СО на 8
A15: Комплект принадлежностей для душевой: коврик нескользящий, занавеска, полка для туалетных принадлежностей, вешалка настенная | B15: компл | C15: 62 | D15: 68 | E15: 6 | F15: 1 | G15: ВОР больше СО на 6
A16: Запарник с крышкой | B16: комплект | C16: 6 | D16: 12 | E16: 6 | F16: 2 | G16: ВОР больше СО на 6
... A45: Дозатор антисептика бесконтактный | B45: шт | C45: 6 | D45: 5 | E45: -1 | F45: 1 | G45: ВОР меньше СО на 1
A46: Скамья гардеробная; 854х390х475(h) мм | B46: шт | C46: 16 | F46: 0 | G46: нет прямой пары в ВОРе; близкая строка ВОРа отнесена к «Скамья гардеробная 854х390х475(h) мм» — проверить
A47: Стул для посетителей (материал обивки – к/з); 540х440х820 (h) мм | B47: шт | C47: 13 | F47: 0 | G47: нет прямой пары в ВОРе; близкая строка ВОРа отнесена к «Стул для посетителей (материал обивки – к/з);» — проверить
A48: Шкаф для раздевалок HPL пластик ТС 2-1 (2 секции) Один ярус (64,5, В комплекте — верхняя полка, нижняя полка, штанга и крючок) (ДхВхШ) 624х1950х500 | B48: шт | C48: 9 | F48: 0 | G48: нет прямой пары в ВОРе; близкая строка ВОРа отнесена к «Шкаф для раздевалок HPL пластик ТС 2-1 (2 сек» — проверить
A49: Телефон | B49: шт | C49: 7 | F49: 0 | G49: в ВОРе не найдено — позиция к закупке сверх ведомости (проверить)
A50: Банкетка параметрическая Габаритный размер 1000х450х450м; - Материал фанера ФСФ сорт 2/2 15мм; - Радиусная шлифовка кромки; - Обработка антисептическими составами | B50: шт | C50: 4 | F50: 0 | G50: нет прямой пары в ВОРе; близкая строка ВОРа отнесена к «Банкетка параметрическая. - Габаритный размер» — проверить
A51: Стеллаж сборный со сплошными полками (5 полок, нагрузка на полку 100 кг); 1000х600х2000(h) мм | B51: шт | C51: 4 | F51: 0 | G51: нет прямой пары в ВОРе; близкая строка ВОРа отнесена к «Стеллаж сборный со сплошными полками (5 полок» — проверить
A52: Укладка для оказания скорой медицинской помощи (общепрофильная) | B52: компл | C52: 2 | F52: 0 | G52: в ВОРе не найдено — позиция к закупке сверх ведомости (проверить)
A53: Стеллаж-шпилька кондитерский. Габариты: 560х520х1800 мм | B53: шт | C53: 2 | F53: 0 | G53: нет прямой пары в ВОРе; близкая строка ВОРа отнесена к «Стеллаж-шпилька Габариты: 560х520х1800 мм» — проверить
A54: Шкаф холодильный среднетемпературный Э1Ф, 220В, 169кВтч/год Габаритные: размеры: 595x650x1860мм | B54: шт | C54: 2 | F54: 0 | G54: нет прямой пары в ВОРе; близкая строка ВОРа отнесена к «Шкаф холодильный среднетемпературный Э1Ф, 220» — проверить
A55: Окно кассира для передачи билет/деньги Машина контрольно-кассовая; Э: 1 ф, 220 В, 0,25 кВт; Габариты 400х400х225 (h) мм | B55: шт | C55: 1 | F55: 0 | G55: нет прямой пары в ВОРе; близкая строка ВОРа отнесена к «Окно кассира для передачи Билет/деньги Машина» — проверить
A56: Лифт размером 1100х2100 Назначение и марка лифта: Пассажирский, для пожарных подразделений 1 Грузоподъёмность: кг 1000 2 Скорость движения кабины: м/с 1,0 - 1,6 3 Высота подъёма: м 4,5 4 Количество остановок/шахтных дверей: шт. 2 5 Характеристика электрической сети (напряжение, род тока) 6 Мощность потребляемая 11 кВт, Потребляемый ток в период пуска 36 А 7 Номинальный ток 22,5 А | B56: шт | C56: 1 | F56: 0 | G56: в ВОРе не найдено — позиция к закупке сверх ведомости (проверить)
A57: Защитная бросковая сетка на торцах и радиусах для арены 60х30м | B57: комплект | C57: 1 | F57: 0 | G57: нет прямой пары в ВОРе; близкая строка ВОРа отнесена к «Защитная бросковая сетка на торцах и радиусах» — проверить
... A62: Стеллаж сборный со сплошными полками (5 полок, нагрузка на полку 200 кг); 2000х600х2000(h) мм | B62: шт | C62: 1 | F62: 0 | G62: нет прямой пары в ВОРе; близкая строка ВОРа отнесена к «Стеллаж сборный со сплошными полками (5 полок» — проверить
A63: (объединено) Стол рабочий прямой; 1200х700х750(h) мм | B63: шт | C63: 0 | D63: 0 | E63: 0 | F63: 0 | G63: объединено со строкой выше — два написания одного наименования
A64: Габаритные размеры 1200х335х435 (ДхШхВ) мм Ванна моечная цельнотянутая односекционная (комплектуется сифоном), Внутренний размер емкости 400х500х250мм, материал – нержавеющая сталь. Каркас уголок - оцинкованная сталь. | B64: шт | C64: 1 | F64: 0 | G64: нет прямой пары в ВОРе; близкая строка ВОРа отнесена к «Ванна моечная цельнотянутая односекционная (к» — проверить
A65: сталь. Габаритные размеры примерно, 600х600х870мм Стерилизатор для ножей. Мощность лампы или ламп не менее 15Вт. Номинальное напряжение 230В±(23)В, рабочее напряжение 230В±(23)В. Габаритные размеры не более (500х155х620)мм. Предназначен для дезинфекции ножей. Процесс стерилизации происходит за счет работы ультрафиолетовой лампы. Кнопка включения и таймер находятся на передней и/или боковой панели стерилизатора. Таймер не менее чем на 50 минут. Вместе с изделием поставляется ультрафиолетовая лампа не менее 1 шт. Материал изготовления корпуса – нержавеющая пищевая сталь. Материал должен быть разрешен Минздравсоцразвитием России к контакту с пищевыми продуктами. | B65: шт | C65: 1 | F65: 0 | G65: нет прямой пары в ВОРе; близкая строка ВОРа отнесена к «Стерилизатор для ножей. Мощность лампы или ла» — проверить
A66: Зонт вытяжной пристенный АЛТЭК ЗВП 14/7 без фильтров, без подсветки, металл AISI 430, Габаритные размеры:1400 х 700 х 350 марка ЗВП 14/7, подключение осуществляется от системы вентиляции | B66: шт | C66: 1 | F66: 0 | G66: нет прямой пары в ВОРе; близкая строка ВОРа отнесена к «Зонт вытяжной пристенный АЛТЭК ЗВП 14/7 без ф» — проверить
A67: 700х700х2200 Контейнер 90л полипропилен d=42,5см h=85см с крышкой на колесах для пищевых отходов | B67: шт | C67: 1 | F67: 0 | G67: нет прямой пары в ВОРе; близкая строка ВОРа отнесена к «Контейнер 90л полипропилен d=42,5см h=85см с » — проверить
A68: мм Персональный компьютер (моноблок) с периферией, источник бесперебойного питания, сетевой фильтр шнур 3 м; Э: 1 ф., 220 В, 0,6 кВт, подключение к интернету, локальной сети | B68: шт | C68: 1 | F68: 0 | G68: нет прямой пары в ВОРе; близкая строка ВОРа отнесена к «Персональный компьютер (моноблок) с периферие» — проверить
A69: Диспенсер для бумажных полотенец Сушилка для рук, настенная; Э: 1ф, 220В, 1.2кВт | B69: шт | C69: 1 | F69: 0 | G69: в ВОРе не найдено — позиция к закупке сверх ведомости (проверить)
A70: Сетка заградительная капроновая, ячейка 40х40 мм, нить диаметром 5 мм, система для монтажа, Длина 60 м, высота 6,5 м | B70: 2 м | C70: 826 | D70: 826 | E70: 0 | F70: 1 | G70: сходится
A71: Зрительские кресла стационарные. Размеры кресла 500×500×980 мм шт | B71: шт | C71: 200 | D71: 200 | E71: 0 | F71: 1 | G71: сходится
A72: Шкафчик гардеробный для хоккеистов (для полевого игрока); 800х600х2000(h) мм в комплекте со скамьей | B72: шт | C72: 138 | D72: 138 | E72: 0 | F72: 3 | G72: сходится
A73: Дозатор для жидкого мыла | B73: шт | C73: 60 | D73: 60 | E73: 0 | F73: 3 | G73: сходится
...

Sheet Правки
A1: ВСЕ ПРАВКИ, ВНЕСЁННЫЕ В ЛИСТ «СПЕЦИФИКАЦИЯ» — можно проверить каждую и при желании удалить этот лист
A2: Строка | B2: Колонка | C2: Было | D2: Стало | E2: Что сделано
A3: 3 | B3: K — Примечание | C3: ВОР 01-01-01, логистика | D3: ВОР 01-01-01, логистика; Источник: 03-01/07.21П-ООС.ТЧ. л 47 (Файл: 03-01_07.21П- ПЗУ.pdf, стр.: 178 179) | E3: ссылка на документ перенесена из «Тип, марка» в примечание
A4: 3 | B4: C — Тип, марка | C4: 03-01/07.21П-ООС.ТЧ. л 47 (Файл: 03-01_07.21П- ПЗУ.pdf, стр.: 178 179) | E4: ссылка на документ убрана из «Тип, марка»
A5: 4 | B5: K — Примечание | C5: ВОР 01-01-01, логистика | D5: ВОР 01-01-01, логистика; Источник: 03-01/07.21П-ПОС.ТЧ. Приложение Д л. 179,187 (Файл: 03-01_07.21П-КР.pdf, стр.: 179) | E5: ссылка на документ перенесена из «Тип, марка» в примечание
A6: 4 | B6: C — Тип, марка | C6: 03-01/07.21П-ПОС.ТЧ. Приложение Д л. 179,187 (Файл: 03-01_07.21П-КР.pdf, стр.: 179) | E6: ссылка на документ убрана из «Тип, марка»
A7: 5 | B7: K — Примечание | C7: ВОР 04-01-01, логистика | D7: ВОР 04-01-01, логистика; Источник: 03-01/07.21П-ИОС.1.5. л.10 (Файл: 03-01_07.21П- ИОС.1.5.pdf, стр.: 10) | E7: ссылка на документ перенесена из «Тип, марка» в примечание
A8: 5 | B8: C — Тип, марка | C8: 03-01/07.21П-ИОС.1.5. л.10 (Файл: 03-01_07.21П- ИОС.1.5.pdf, стр.: 10) | E8: ссылка на документ убрана из «Тип, марка»
A9: 6 | B9: K — Примечание | C9: ВОР 06-01-01, логистика | D9: ВОР 06-01-01, логистика; Источник: 03-01/07.21П-ПОС.ТЧ. Приложение Д. л. 179 (Файл: 03-01_07.21П-ПОС.pdf, стр.: 1) | E9: ссылка на документ перенесена из «Тип, марка» в примечание
A10: 6 | B10: C — Тип, марка | C10: 03-01/07.21П-ПОС.ТЧ. Приложение Д. л. 179 (Файл: 03-01_07.21П-ПОС.pdf, стр.: 1) | E10: ссылка на документ убрана из «Тип, марка»
A11: 7 | B11: K — Примечание | C11: ВОР 06-01-01, логистика | D11: ВОР 06-01-01, логистика; Источник: 03-01/07.21П-ПОС.ТЧ. Приложение Д. л. 179 (Файл: 03-01_07.21П-ПОС.pdf, стр.: 1) | E11: ссылка на документ перенесена из «Тип, марка» в примечание
A12: 7 | B12: C — Тип, марка | C12: 03-01/07.21П-ПОС.ТЧ. Приложение Д. л. 179 (Файл: 03-01_07.21П-ПОС.pdf, стр.: 1) | E12: ссылка на документ убрана из «Тип, марка»
A13: 8 | B13: K — Примечание | C13: ВОР 06-01-01, логистика | D13: ВОР 06-01-01, логистика; Источник: 03-01/07.21П-ПОС.ТЧ. Приложение Д. л. 180 (Файл: 03-01_07.21П-ПОС.pdf, стр.: 1) | E13: ссылка на документ перенесена из «Тип, марка» в примечание
A14: 8 | B14: C — Тип, марка | C14: 03-01/07.21П-ПОС.ТЧ. Приложение Д. л. 180 (Файл: 03-01_07.21П-ПОС.pdf, стр.: 1) | E14: ссылка на документ убрана из «Тип, марка»
A15: 9 | B15: K — Примечание | C15: ВОР 06-01-02, логистика | D15: ВОР 06-01-02, логистика; Источник: 03-01/07.21П-ПОС.ТЧ. Приложение Д. л. 186 (Файл: 03-01_07.21П-ПОС.pdf, стр.: 1) | E15: ссылка на документ перенесена из «Тип, марка» в примечание
A16: 9 | B16: C — Тип, марка | C16: 03-01/07.21П-ПОС.ТЧ. Приложение Д. л. 186 (Файл: 03-01_07.21П-ПОС.pdf, стр.: 1) | E16: ссылка на документ убрана из «Тип, марка»
A17: 10 | B17: K — Примечание | C17: ВОР 06-01-02, логистика | D17: ВОР 06-01-02, логистика; Источник: 03-01/07.21П-ПОС.ТЧ. Приложение Д. л. 181-182 (Файл: 03-01_07.21П-ПОС.pdf, стр.: 1) | E17: ссылка на документ перенесена из «Тип, марка» в примечание
A18: 10 | B18: C — Тип, марка | C18: 03-01/07.21П-ПОС.ТЧ. Приложение Д. л. 181-182 (Файл: 03-01_07.21П-ПОС.pdf, стр.: 1) | E18: ссылка на документ убрана из «Тип, марка»
A19: 11 | B19: K — Примечание | C19: ВОР 06-01-02, логистика | D19: ВОР 06-01-02, логистика; Источник: 03-01/07.21П-ПОС.ТЧ. Приложение Д. л. 186 (Файл: 03-01_07.21П-ПОС.pdf, стр.: 1) | E19: ссылка на документ перенесена из «Тип, марка» в примечание
A20: 11 | B20: C — Тип, марка | C20: 03-01/07.21П-ПОС.ТЧ. Приложение Д. л. 186 (Файл: 03-01_07.21П-ПОС.pdf, стр.: 1) | E20: ссылка на документ убрана из «Тип, марка»
A21: 12 | B21: K — Примечание | C21: ВОР 06-01-02, логистика | D21: ВОР 06-01-02, логистика; Источник: 03-01/07.21П-ПОС.ТЧ. Приложение Д. л. 181-182 (Файл: 03-01_07.21П-ПОС.pdf, стр.: 1) | E21: ссылка на документ перенесена из «Тип, марка» в примечание
A22: 12 | B22: C — Тип, марка | C22: 03-01/07.21П-ПОС.ТЧ. Приложение Д. л. 181-182 (Файл: 03-01_07.21П-ПОС.pdf, стр.: 1) | E22: ссылка на документ убрана из «Тип, марка»
A23: 13 | B23: K — Примечание | C23: ВОР 06-01-02, логистика | D23: ВОР 06-01-02, логистика; Источник: 03-01/07.21П-ПОС.ТЧ. Приложение Д. л. 186 (Файл: 03-01_07.21П-ПОС.pdf, стр.: 1) | E23: ссылка на документ перенесена из «Тип, марка» в примечание
A24: 13 | B24: C — Тип, марка | C24: 03-01/07.21П-ПОС.ТЧ. Приложение Д. л. 186 (Файл: 03-01_07.21П-ПОС.pdf, стр.: 1) | E24: ссылка на документ убрана из «Тип, марка»
A25: 14 | B25: K — Примечание | C25: ВОР 06-01-02, логистика | D25: ВОР 06-01-02, логистика; Источник: 03-01/07.21П-ПОС.ТЧ. Приложение Д. л. 184 (Файл: 03-01_07.21П-ПОС.pdf, стр.: 1) | E25: ссылка на документ перенесена из «Тип, марка» в примечание
A26: 14 | B26: C — Тип, марка | C26: 03-01/07.21П-ПОС.ТЧ. Приложение Д. л. 184 (Файл: 03-01_07.21П-ПОС.pdf, стр.: 1) | E26: ссылка на документ убрана из «Тип, марка»
A27: 15 | B27: K — Примечание | C27: ВОР 06-01-04, логистика | D27: ВОР 06-01-04, логистика; Источник: 03-01/07.21П-ПОС.ТЧ. Приложение Д л. 186 (Файл: 03-01_07.21П-ИОС4.4.pdf, стр.: 186) | E27: ссылка на документ перенесена из «Тип, марка» в примечание
A28: 15 | B28: C — Тип, марка | C28: 03-01/07.21П-ПОС.ТЧ. Приложение Д л. 186 (Файл: 03-01_07.21П-ИОС4.4.pdf, стр.: 186) | E28: ссылка на документ убрана из «Тип, марка»
A29: 16 | B29: K — Примечание | C29: ВОР 07-01-02, логистика | D29: ВОР 07-01-02, логистика; Источник: 03-01/07.21П-ПЗУ.ГЧ л.6 (Файл: 03-01_07.21П- ПЗУ.pdf, стр.: 55) | E29: ссылка на документ перенесена из «Тип, марка» в примечание
A30: 16 | B30: C — Тип, марка | C30: 03-01/07.21П-ПЗУ.ГЧ л.6 (Файл: 03-01_07.21П- ПЗУ.pdf.pdf, стр.: 55) | E30: ссылка на документ убрана из «Тип, марка»
A31: 17 | B31: K — Примечание | C31: ВОР 07-01-04, логистика | D31: ВОР 07-01-04, логистика; Источник: 03-01/07.21П-ИОС.1.4.ГЧ л.2 (Файл: 03-01_07.21П- ИОС.1.4.pdf, стр.: 18 19 20 21) | E31: ссылка на документ перенесена из «Тип, марка» в примечание
A32: 17 | B32: C — Тип, марка | C32: 03-01/07.21П-ИОС.1.4.ГЧ л.2 (Файл: 03-01_07.21П- ИОС.1.4.pdf, стр.: 18 19 20 21) | E32: ссылка на документ убрана из «Тип, марка»
A33: 384 | B33: K — Примечание | C33: ВОР, нет в СО | D33: ВОР, нет в СО; Источник: 03-01/07.21П-ИОС 2.1.ГЧ Спецификация (Файл: 03- 01_07.21П-ИОС.2.pdf стр.: 1 2 3 4 5 6) | E33: ссылка на документ перенесена из «Тип, марка» в примечание
A34: 384 | B34: C — Тип, марка | C34: 03-01/07.21П-ИОС 2.1.ГЧ Спецификация (Файл: 03- 01_07.21П-ИОС.2.pdf стр.: 1 2 3 4 5 6) | E34: ссылка на документ убрана из «Тип, марка»
A35: 385 | B35: K — Примечание | C35: ВОР, нет в СО | D35: ВОР, нет в СО; Источник: 03-01/07.21П-ИОС 2.1.ГЧ Спецификация (Файл: 03- 01_07.21П-ИОС.2.pdf стр.: 1 2 3 4 5 6) | E35: ссылка на документ перенесена из «Тип, марка» в примечание
A36: 385 | B36: C — Тип, марка | C36: 03-01/07.21П-ИОС 2.1.ГЧ Спецификация (Файл: 03- 01_07.21П-ИОС.2.pdf стр.: 1 2 3 4 5 6) | E36: ссылка на документ убрана из «Тип, марка»
A37: 386 | B37: K — Примечание | C37: ВОР, нет в СО | D37: ВОР, нет в СО; Источник: 03-01/07.21П-ИОС 2.1.ГЧ Спецификация (Файл: 03- 01_07.21П-ИОС.2.pdf стр.: 1 2 3 4 5 6) | E37: ссылка на документ перенесена из «Тип, марка» в примечание
A38: 386 | B38: C — Тип, марка | C38: 03-01/07.21П-ИОС 2.1.ГЧ Спецификация (Файл: 03- 01_07.21П-ИОС.2.pdf стр.: 1 2 3 4 5 6) | E38: ссылка на документ убрана из «Тип, марка»
A39: 387 | B39: K — Примечание | C39: ВОР, нет в СО | D39: ВОР, нет в СО; Источник: 03-01/07.21П-ИОС 2.1.ГЧ Спецификация (Файл: 03- 01_07.21П-ИОС.2.pdf стр.: 1 2 3 4 5 6) | E39: ссылка на документ перенесена из «Тип, марка» в примечание
A40: 387 | B40: C — Тип, марка | C40: 03-01/07.21П-ИОС 2.1.ГЧ Спецификация (Файл: 03- 01_07.21П-ИОС.2.pdf стр.: 1 2 3 4 5 6) | E40: ссылка на документ убрана из «Тип, марка»
...
